<mujoco model="onshape">
    <compiler angle="radian"/>

    <asset>
        <mesh name="arm" file="arm.stl"/>
        <mesh name="leg_h" file="leg_h.stl"/>
        <mesh name="battery" file="battery.stl"/>
        <mesh name="hip" file="hip.stl"/>
        <mesh name="ak80-8" file="ak80-8.stl"/>
        <mesh name="leg_v" file="leg_v.stl"/>
        <mesh name="part_1" file="part_1.stl"/>
    </asset>

    <visual>
        <global offwidth="1920" offheight="1080"/>
    </visual>

    <worldbody>
        <body name="leg_h">
            <freejoint />
            <geom pos="-0.555 0.0125 -0.485" quat="1 0 0 0" type="mesh" rgba="0.796078 0.823529 0.937255 1" mesh="arm"/>
            <geom pos="0.2525 0.054 -0.9875" quat="1 0 0 0" type="mesh" rgba="0.796078 0.823529 0.937255 1" mesh="leg_h"/>
            <geom pos="-0.49 -0.05 -0.56" quat="0 0 0 1" type="mesh" rgba="0.796078 0.823529 0.937255 1" mesh="battery"/>

            <body name="ak80-8" pos="0 0 0" quat="0 -0.707107 0 0.707107">
                <joint name="hip2" pos="0 0 0" axis="0 0 1" range="-0.785398 0.785398" actuatorfrcrange="-1 1"/>
                <geom pos="0 0 0.555" quat="0.5 0.5 0.5 -0.5" type="mesh" rgba="0.796078 0.823529 0.937255 1" mesh="hip"/>
                <geom quat="0.5 0.5 0.5 -0.5" type="mesh" rgba="0.615686 0.811765 0.929412 1" mesh="ak80-8"/>

                    <body name="leg_h_2" pos="0 0 0.265" quat="0 0.707107 -0.707107 0">
                        <!-- <joint name="hip1" pos="0 0 0" axis="0 0 1" range="-0.785398 0.785398" actuatorfrcrange="-1 1"/> -->
                        <geom pos="-0.05 -0.56 0.855" quat="0.5 -0.5 0.5 0.5" type="mesh" rgba="0.796078 0.823529 0.937255 1" mesh="battery"/>
                        <geom pos="0.054 -0.9875 -0.0125" quat="0.5 -0.5 -0.5 -0.5" type="mesh" rgba="0.796078 0.823529 0.937255 1" mesh="leg_h"/>
                        <geom pos="-0.0125 -0.485 0.82" quat="0.5 -0.5 0.5 0.5" type="mesh" rgba="0.796078 0.823529 0.937255 1" mesh="arm"/>
                        
                        <body name="leg_v" pos="0.054 0 0" quat="0.707107 0 -0.707107 0">
                            <!-- <joint name="hip_offset_slider_left" pos="0 0 0" axis="0 0 1" type="slide" actuatorfrcrange="-1 1"/> -->
                            <geom pos="-0.0125 -0.9875 0" quat="0.707107 -0.707107 0 0" type="mesh" rgba="0.796078 0.823529 0.937255 1" mesh="leg_v"/>
                            <geom pos="0.14908 -0.3625 -0.0125974" quat="0 0 -0.707107 0.707107" type="mesh" rgba="0.796078 0.823529 0.937255 1" mesh="part_1"/>
                        </body>
                    </body>
            </body>

            <body name="leg_v_2" pos="0.265 0.054 0" quat="0.707107 0.707107 0 0">
                <!-- <joint name="hip_offset_slider_right" pos="0 0 0" axis="0 0 1" type="slide" actuatorfrcrange="-1 1"/> -->
                <geom pos="-0.0125 -0.9875 0" quat="0.707107 -0.707107 0 0" type="mesh" rgba="0.796078 0.823529 0.937255 1" mesh="leg_v"/>
                <geom pos="-0.14908 -0.3625 -0.0124026" quat="0.707107 0.707107 0 0" type="mesh" rgba="0.796078 0.823529 0.937255 1" mesh="part_1"/>
            </body>
        </body>
    </worldbody>

    <contact>
        <exclude body1="leg_1" body2="leg_2" />
    </contact>

    <actuator>
        <motor name="hip_joint_act" joint="hip" forcerange="-25 25" />
    </actuator>

</mujoco>
