<?xml version='1.0' encoding='utf-8'?>
<mujoco model="OnshapeRobot">
  <compiler angle="degree" />
  <option timestep="0.005" />
  <worldbody>
    <body name="Left_leg_&lt;1&gt;" pos="0.0 0.0 0.0" quat="1.0 0.0 0.0 0.0">
      <geom mass="0.07376726465798017" type="mesh" mesh="Left_leg_&lt;1&gt;" rgba="0.8 0.6 0.4 1" />
      <body name="Right_leg_&lt;1&gt;" pos="0.0 0.0 0.0" quat="-1.0 0.0 0.0 0.0">
        <geom mass="0.0529787507353837" type="mesh" mesh="Right_leg_&lt;1&gt;" rgba="0.8 0.6 0.4 1" />
        <joint name="joint_Right_leg_&lt;1&gt;" type="hinge"
          pos="1.1291100711216299e-05 3.5100000000000006e-05 0.000153342845533572"
          axis="0.0 1.0 0.0" />
        <body name="Right_foot_&lt;1&gt;" pos="0.0 0.0 0.0" quat="-1.0 0.0 0.0 0.0">
          <geom mass="0.05123214551208461" type="mesh" mesh="Right_foot_&lt;1&gt;"
            rgba="0.8 0.6 0.4 1" />
        </body>
      </body>
      <body name="Right_arm_&lt;1&gt;" pos="0.0 0.0 0.0" quat="-1.0 0.0 0.0 0.0">
        <geom mass="0.059112686530484994" type="mesh" mesh="Right_arm_&lt;1&gt;"
          rgba="0.8 0.6 0.4 1" />
        <body name="Right_battery_&lt;1&gt;" pos="0.0 0.0 0.0" quat="-1.0 0.0 0.0 0.0">
          <geom mass="0.01" type="mesh" mesh="Right_battery_&lt;1&gt;" rgba="0.8 0.6 0.4 1" />
        </body>
      </body>
    </body>
    <body name="Right_battery_&lt;2&gt;" pos="0.0 0.0 0.0" quat="1.0 0.0 0.0 0.0">
      <geom mass="0.01" type="mesh" mesh="Right_battery_&lt;2&gt;" rgba="0.8 0.6 0.4 1" />
      <body name="Left_arm_&lt;1&gt;" pos="0.0 0.0 0.0" quat="-1.0 0.0 0.0 0.0">
        <geom type="mesh" mass="0.06219204786445871" mesh="Left_arm_&lt;1&gt;" rgba="0.8 0.6 0.4 1" />
      </body>
    </body>
    <body name="Left_foot_&lt;1&gt;" pos="0.0 0.0 0.0" quat="1.0 0.0 0.0 0.0">
      <geom mass="0.05123214551208457" type="mesh" mesh="Left_foot_&lt;1&gt;" rgba="0.8 0.6 0.4 1" />
    </body>
  </worldbody>
  <asset>
    <mesh name="Right_foot_&lt;1&gt;" file="meshes/Right_foot_&lt;1&gt;_JFD.stl" />
    <mesh name="Left_leg_&lt;1&gt;" file="meshes/Left_leg_&lt;1&gt;_JFH.stl" />
    <mesh name="Right_leg_&lt;1&gt;" file="meshes/Right_leg_&lt;1&gt;_JFL.stl" />
    <mesh name="Right_arm_&lt;1&gt;" file="meshes/Right_arm_&lt;1&gt;_JFP.stl" />
    <mesh name="Left_arm_&lt;1&gt;" file="meshes/Left_arm_&lt;1&gt;_JFT.stl" />
    <mesh name="Right_battery_&lt;1&gt;" file="meshes/Right_battery_&lt;1&gt;_JFX.stl" />
    <mesh name="Right_battery_&lt;2&gt;" file="meshes/Right_battery_&lt;2&gt;_JFX.stl" />
    <mesh name="Left_foot_&lt;1&gt;" file="meshes/Left_foot_&lt;1&gt;_JFf.stl" />
  </asset>
</mujoco>