<mujoco model="onshape">
  <option iterations="50" timestep="0.001" solver="PGS" gravity="0 0 -9.81" />

  <compiler angle="radian" meshdir="meshes" eulerseq="zyx" autolimits="true" />

  <default>
    <joint limited="true" damping="0.01" armature="0.01" frictionloss="0.01" />
    <geom condim="4" contype="1" conaffinity="15" friction="0.9 0.2 0.2" solref="0.001 2" />
    <motor ctrllimited="true" />
    <equality solref="0.001 2" />
    <position kp="35" kv="1.9" ctrlrange="-1.6 1.6" />
    <default class="visualgeom">
      <geom material="visualgeom" condim="1" contype="0" conaffinity="0" />
    </default>
  </default>

  <asset>
    <mesh name="right_leg_collision" file="right_leg_collision.stl" />
    <mesh name="left_leg_collision" file="left_leg_collision.stl" />
    <texture name="texplane" type="2d" builtin="checker" rgb1=".0 .0 .0" rgb2=".8 .8 .8" width="100"
      height="100" />
    <material name="matplane" reflectance="0." texture="texplane" texrepeat="1 1" texuniform="true" />
    <material name="visualgeom" rgba="0.5 0.9 0.2 1" />
  </asset>

  <worldbody>
    <light directional="true" diffuse="0.4 0.4 0.4" specular="0.1 0.1 0.1" pos="0 0 5.0"
      dir="0 0 -1" castshadow="false" />
    <light directional="true" diffuse="0.6 0.6 0.6" specular="0.2 0.2 0.2" pos="0 0 4" dir="0 0 -1" />
    <geom name="ground" type="plane" pos="0 0 0" size="100 100 0.001" quat="1 0 0 0"
      material="matplane" condim="3" conaffinity="15" />
    <camera name="fixed" pos="0 -3.0 0.5" xyaxes="1 0 0 0 0 1" />
    <camera name="track" mode="trackcom" pos="0 -3.0 0.5" xyaxes="1 0 0 0 0 1" />
    <body name="root" pos="0 0 0.2" quat="1 0 0 0">
      <freejoint name="root" />
      <site name="imu" size="0.01" pos="0 0 0" />
      <geom type="mesh" rgba="0.623813 0.71154 0.933089 1" mesh="right_leg_collision" contype="1"
        conaffinity="0" density="0" group="1" class="visualgeom" />
      <geom type="mesh" rgba="0.623813 0.71154 0.933089 1" mesh="right_leg_collision" />
      <body name="left_leg" pos="-0.0208226 0.0139365 -0.0162078" quat="0.5 -0.5 -0.5 0.5">
        <inertial pos="0.015831 0.0865829 -0.0193168" quat="0.429494 0.898507 -0.0880727 0.0215063"
          mass="0.413951" diaginertia="0.00218976 0.00159507 0.000895587" />
        <joint name="hip" pos="0 0 0" axis="0 0 1" range="-1.5708 1.5708" actuatorfrcrange="-1 1" />
        <geom type="mesh" rgba="0.576017 0.668568 0.916262 1" mesh="left_leg_collision" contype="1"
          conaffinity="0" density="0" group="1" class="visualgeom" />
        <geom type="mesh" rgba="0.576017 0.668568 0.916262 1" mesh="left_leg_collision" />
      </body>
    </body>
  </worldbody>

  <!-- <actuator>
    <motor name="hip" joint="hip" ctrllimited="true" ctrlrange="-1 1" gear="1" />
  </actuator> -->

  <actuator>
    <position name="hip_joint_act" joint="hip" ctrlrange="-1.6 1.6" />
  </actuator>

  <sensor>
    <actuatorpos name="hip_p" actuator="hip_joint_act" />
    <actuatorvel name="hip_v" actuator="hip_joint_act" />
    <actuatorfrc name="hip_f" actuator="hip_joint_act" noise="0.001" />
    <framequat name="orientation" objtype="site" noise="0.001" objname="imu" />
    <gyro name="angular-velocity" site="imu" noise="0.005" cutoff="34.9" />
  </sensor>
</mujoco>