<robot name="onshape">
  <link name="right_leg">
    <visual>
      <origin xyz="0 0 0" rpy="0 -0 0" />
      <geometry>
        <mesh filename="right_leg_visual.stl" />
      </geometry>
      <material name="right_leg_material">
        <color rgba="0.62381260296990748149 0.71154009872000811843 0.93308919815670299247 1.0" />
      </material>
    </visual>
    <collision>
      <origin xyz="0 0 0" rpy="0 -0 0" />
      <geometry>
        <mesh filename="right_leg_collision.stl" />
      </geometry>
    </collision>
    <inertial>
      <origin xyz="-0.029251686360109632051 0.030419294575498329047 -0.10611825963484414204"
        rpy="0 0 0" />
      <mass value="0.39597688179033829758" />
      <inertia ixx="0.0011937054740806831137" ixy="4.453328848433648501e-05"
        ixz="0.00038867615933425430372" iyy="0.0020223835438831542187"
        iyz="7.6511419319811566119e-05" izz="0.0011525854397805663717" />
    </inertial>
  </link>

  <link name="left_leg">
    <visual>
      <origin xyz="0 0 0" rpy="0 -0 0" />
      <geometry>
        <mesh filename="left_leg_visual.stl" />
      </geometry>
      <material name="left_leg_material">
        <color rgba="0.57601720395855515733 0.66856832501362561949 0.91626224830531333154 1.0" />
      </material>
    </visual>
    <collision>
      <origin xyz="0 0 0" rpy="0 -0 0" />
      <geometry>
        <mesh filename="left_leg_collision.stl" />
      </geometry>
    </collision>
    <inertial>
      <origin xyz="0.015830994313756244218 0.08658293857595017462 -0.019316826607899253987"
        rpy="0 0 0" />
      <mass value="0.4139512965380884868" />
      <inertia ixx="0.0021694157004607502251" ixy="-0.00010184426068827120439"
        ixz="5.0544566398024546997e-05" iyy="0.0011859207889260213291"
        iyz="-0.00035136756416844909827" izz="0.0013250893011849313764" />
    </inertial>
  </link>

  <joint name="hip" type="revolute">
    <origin xyz="-0.020822569739601518024 0.013936485767817355028 -0.016207791599193055454"
      rpy="-1.570796326794896558 -0 1.570796326794896558" />
    <parent link="right_leg" />
    <child link="left_leg" />
    <axis xyz="0 0 1" />
    <limit effort="1" velocity="20" lower="-1.570796326794896558" upper="1.570796326794896558" />
    <joint_properties friction="0.0" />
  </joint>


</robot>