<mujoco model="mugatu">
  <compiler angle="radian" meshdir="assets" autolimits="true" />

  <asset>
    <material name="black" rgba="0.2 0.2 0.2 1" />

    <mesh file="left_arm.STL" />
    <mesh file="left_foot.STL" />
    <mesh file="left_hand.STL" />
    <mesh file="left_leg.STL" />
    <mesh file="right_arm.STL" />
    <mesh file="right_foot.STL" />
    <mesh file="right_hand.STL" />
    <mesh file="right_leg.STL" />
  </asset>

  <default>
    <mesh scale="1 1 1" />
    <geom type="mesh" />
    <joint damping="1.084" armature="0.045" frictionloss="0.03" />
    <position kp="21.1" ctrlrange="-1.6 1.6" forcerange="-5 5" />
    <default class="visual">
      <geom material="black" contype="0" conaffinity="0" group="2" />
    </default>
    <default class="collision">
      <geom group="3" />
    </default>
  </default>

  <worldbody>
    
    <body name="left_leg" pos="0 0 0.19" quat="0.9962 0.1094 0 0">
      
      <freejoint />
      <inertial pos="-0.020135 0.0060914 -0.037528" mass="0.074376" diaginertia="0.00016466 0.00017142 3.6129E-05" />
      <geom name="left_leg_geom" mesh="left_leg" class="visual" />

      
      <body name="left_foot" pos="0 0 0">
        <inertial pos="-0.041798 -0.010453 -0.14105" mass="0.13" diaginertia="3.5093E-05 1.6948E-05 4.6282E-05" />
        <geom name="left_foot_geom" mesh="left_foot" class="visual" />
        <geom name="left_foot_geom_c" mesh="left_foot" class="collision" condim="3" friction="1 0.005 0.0001" />
      </body>

      
      <body name="right_arm" pos="0 0 0">
        <inertial pos="0.04926 0.00272 -0.01279" mass="0.05925" diaginertia="9.294E-05 0.00011438 3.013E-05" />
        <geom name="right_arm_geom" mesh="right_arm" class="visual" />

        
        <body name="right_hand" pos="0 0 0">
          <inertial pos="0.063219 0.006502 -0.096732" mass="0.047" diaginertia="1.6385E-05 4.4778E-06 1.3827E-05" />
          <geom name="right_hand_geom" mesh="right_hand" class="visual" />
        </body>
      </body>

      
      <body name="right_leg" pos="0 0 0">
        <joint name="hip_joint" pos="0 0 0" axis="1 0 0" limited="true" range="-1.6 1.6" />
        <inertial pos="0.024301 0.0087941 -0.048016" mass="0.053384" diaginertia="0.00012812 0.00012609 1.6956E-05" />
        <geom name="right_leg_geom" mesh="right_leg" class="visual" />

        
        <body name="right_foot" pos="0 0 0">
          <inertial pos="0.041698 -0.010453 -0.14105" mass="0.13" diaginertia="3.5093E-05 1.6948E-05 4.6282E-05" />
          <geom name="right_foot_geom" mesh="right_foot" class="visual" />
          <geom name="right_foot_geom_c" mesh="right_foot" class="collision" condim="3" friction="1 0.005 0.0001" />
        </body>

        
        <body name="left_arm" pos="0 0 0">
          <inertial pos="-0.047956 0.0025663 -0.01277" mass="0.062169" diaginertia="8.9606E-05 0.00011168 3.1289E-05" />
          <geom name="left_arm_geom" mesh="left_arm" class="visual" />

          
          <body name="left_hand" pos="0 0 0">
            <inertial pos="-0.063219 0.006502 -0.096374" mass="0.047" diaginertia="1.6385E-05 4.4778E-06 1.3827E-05" />
            <geom name="left_hand_geom" mesh="left_hand" class="visual" />
          </body>
        </body>
      </body>
    </body>
  </worldbody>

  <actuator>
    
    <position name="hip_joint_act" joint="hip_joint" ctrlrange="-1.6 1.6" />
  </actuator>
</mujoco>